<?xml version="1.0" encoding="utf-8"?>
<!-- This URDF was automatically created by SolidWorks to URDF Exporter! Originally created by Stephen Brawner (brawner@gmail.com) 
     Commit Version: 1.6.0-1-g15f4949  Build Version: 1.6.7594.29634
     For more information, please see http://wiki.ros.org/sw_urdf_exporter -->
<robot
  name="6wdrobot">
  <link name="dummy">
  </link>  
  <link
    name="base_link">
    <inertial>
      <origin
        xyz="3.25434433893571E-17 -7.87892363847751E-17 0.028309054753637"
        rpy="0 0 0" />
      <mass
        value="8.89985095070989" />
      <inertia
        ixx="0.0873775019369665"
        ixy="-6.18908522780936E-17"
        ixz="-7.10139062453339E-19"
        iyy="0.201411214668191"
        iyz="1.04057366878614E-17"
        izz="0.285825171408563" />
    </inertial>
    <visual>
      <origin
        xyz="0 0 0"
        rpy="0 0 0" />
      <geometry>
        <mesh
          filename="package://six_wheel_drive/meshes/base_link.STL" />
      </geometry>
      <material
        name="">
        <color
          rgba="0.776470588235294 0.756862745098039 0.737254901960784 1" />
      </material>
    </visual>
    <collision>
      <origin
        xyz="0 0 0"
        rpy="0 0 0" />
      <geometry>
        <mesh
          filename="package://six_wheel_drive/meshes/base_link.STL" />
      </geometry>
    </collision>
  </link>

  <joint name="dummy_joint" type="fixed">
     <parent link="dummy"/>
     <child link="base_link"/>
   </joint>

  <link
    name="wheel_1">
    <inertial>
      <origin
        xyz="5.55111512312578E-17 -3.46944695195361E-18 0.0234150828488255"
        rpy="0 0 0" />
      <mass
        value="0.496854720213167" />
      <inertia
        ixx="0.000600193850657454"
        ixy="0"
        ixz="1.61565152047808E-20"
        iyy="0.000600193850657454"
        iyz="4.50998871731038E-20"
        izz="0.00100449326717908" />
    </inertial>
    <visual>
      <origin
        xyz="0 0 0"
        rpy="0 1.5707963267949 -1.5707963267949" />
      <geometry>
        <mesh
          filename="package://six_wheel_drive/meshes/wheel_1.STL" />
      </geometry>
      <material
        name="">
        <color
          rgba="0.501960784313725 0.501960784313725 0.501960784313725 1" />
      </material>
    </visual>
    <collision>
      <origin
        xyz="0 0 0"
        rpy="0 1.5707963267949 -1.5707963267949" />
      <geometry>
        <mesh
          filename="package://six_wheel_drive/meshes/wheel_1.STL" />
      </geometry>
    </collision>
  </link>
  <joint
    name="wj1"
    type="continuous">
    <origin
      xyz="0.22 0.155 0.027"
      rpy="0 0 3.141592654" />
    <parent
      link="base_link" />
    <child
      link="wheel_1" />
    <axis
      xyz="0 -1 0" />
  </joint>
  <link
    name="wheel_2">
    <inertial>
      <origin
        xyz="-5.55111512312578E-17 -6.93889390390723E-18 0.0234150828488254"
        rpy="0 0 0" />
      <mass
        value="0.496854720213167" />
      <inertia
        ixx="0.000600193850657454"
        ixy="0"
        ixz="-3.14427093120379E-21"
        iyy="0.000600193850657454"
        iyz="-1.52762865296402E-22"
        izz="0.00100449326717908" />
    </inertial>
    <visual>
      <origin
        xyz="0 0 0"
        rpy="0 1.5707963267949 1.5707963267949" />
      <geometry>
        <mesh
          filename="package://six_wheel_drive/meshes/wheel_2.STL" />
      </geometry>
      <material
        name="">
        <color
          rgba="0.501960784313725 0.501960784313725 0.501960784313725 1" />
      </material>
    </visual>
    <collision>
      <origin
        xyz="0 0 0"
        rpy="0 1.5707963267949 1.5707963267949" />
      <geometry>
        <mesh
          filename="package://six_wheel_drive/meshes/wheel_2.STL" />
      </geometry>
    </collision>
  </link>
  <joint
    name="wj2"
    type="continuous">
    <origin
      xyz="0.22 -0.155 0.027"
      rpy="3.141592654 0 0" />
    <parent
      link="base_link" />
    <child
      link="wheel_2" />
    <axis
      xyz="0 -1 0" />
  </joint>
  <link
    name="wheel_3">
    <inertial>
      <origin
        xyz="-2.42861286636753E-17 1.73472347597681E-17 0.0234150828488254"
        rpy="0 0 0" />
      <mass
        value="0.496854720213167" />
      <inertia
        ixx="0.000600193850657454"
        ixy="-5.42101086242752E-20"
        ixz="4.78770762399125E-20"
        iyy="0.000600193850657454"
        iyz="3.38815713366649E-20"
        izz="0.00100449326717908" />
    </inertial>
    <visual>
      <origin
        xyz="0 0 0"
        rpy="0 1.5707963267949 -1.5707963267949" />
      <geometry>
        <mesh
          filename="package://six_wheel_drive/meshes/wheel_3.STL" />
      </geometry>
      <material
        name="">
        <color
          rgba="0.501960784313725 0.501960784313725 0.501960784313725 1" />
      </material>
    </visual>
    <collision>
      <origin
        xyz="0 0 0"
        rpy="0 1.5707963267949 -1.5707963267949" />
      <geometry>
        <mesh
          filename="package://six_wheel_drive/meshes/wheel_3.STL" />
      </geometry>
    </collision>
  </link>
  <joint
    name="wj3"
    type="continuous">
    <origin
      xyz="0 0.155 0.027"
      rpy="0 0 3.141592654" />
    <parent
      link="base_link" />
    <child
      link="wheel_3" />
    <axis
      xyz="0 -1 0" />
  </joint>
  <link
    name="wheel_4">
    <inertial>
      <origin
        xyz="2.86229373536173E-17 0 0.0234150828488254"
        rpy="0 0 0" />
      <mass
        value="0.496854720213167" />
      <inertia
        ixx="0.000600193850657454"
        ixy="0"
        ixz="-2.7326617250845E-21"
        iyy="0.000600193850657454"
        iyz="-5.07733050758664E-22"
        izz="0.00100449326717908" />
    </inertial>
    <visual>
      <origin
        xyz="0 0 0"
        rpy="0 1.5707963267949 1.5707963267949" />
      <geometry>
        <mesh
          filename="package://six_wheel_drive/meshes/wheel_4.STL" />
      </geometry>
      <material
        name="">
        <color
          rgba="0.501960784313725 0.501960784313725 0.501960784313725 1" />
      </material>
    </visual>
    <collision>
      <origin
        xyz="0 0 0"
        rpy="0 1.5707963267949 1.5707963267949" />
      <geometry>
        <mesh
          filename="package://six_wheel_drive/meshes/wheel_4.STL" />
      </geometry>
    </collision>
  </link>
  <joint
    name="wj4"
    type="continuous">
    <origin
      xyz="0 -0.155 0.027"
      rpy="3.141592654 0 0" />
    <parent
      link="base_link" />
    <child
      link="wheel_4" />
    <axis
      xyz="0 -1 0" />
  </joint>
  <link
    name="wheel_5">
    <inertial>
      <origin
        xyz="0 1.04083408558608E-17 0.0234150828488254"
        rpy="0 0 0" />
      <mass
        value="0.496854720213167" />
      <inertia
        ixx="0.000600193850657454"
        ixy="-1.6940658945086E-21"
        ixz="1.17900986878341E-20"
        iyy="0.000600193850657454"
        iyz="4.52750976635983E-20"
        izz="0.00100449326717908" />
    </inertial>
    <visual>
      <origin
        xyz="0 0 0"
        rpy="0 1.5707963267949 -1.5707963267949" />
      <geometry>
        <mesh
          filename="package://six_wheel_drive/meshes/wheel_5.STL" />
      </geometry>
      <material
        name="">
        <color
          rgba="0.501960784313725 0.501960784313725 0.501960784313725 1" />
      </material>
    </visual>
    <collision>
      <origin
        xyz="0 0 0"
        rpy="0 1.5707963267949 -1.5707963267949" />
      <geometry>
        <mesh
          filename="package://six_wheel_drive/meshes/wheel_5.STL" />
      </geometry>
    </collision>
  </link>
  <joint
    name="wj5"
    type="continuous">
    <origin
      xyz="-0.22 0.155 0.027"
      rpy="0 0 3.141592654" />
    <parent
      link="base_link" />
    <child
      link="wheel_5" />
    <axis
      xyz="0 -1 0" />
  </joint>
  <link
    name="wheel_6">
    <inertial>
      <origin
        xyz="2.77555756156289E-17 -3.46944695195361E-18 0.0234150828488254"
        rpy="0 0 0" />
      <mass
        value="0.496854720213167" />
      <inertia
        ixx="0.000600193850657454"
        ixy="0"
        ixz="2.16658438655785E-20"
        iyy="0.000600193850657454"
        iyz="6.89724555337065E-23"
        izz="0.00100449326717908" />
    </inertial>
    <visual>
      <origin
        xyz="0 0 0"
        rpy="0 1.5707963267949 1.5707963267949" />
      <geometry>
        <mesh
          filename="package://six_wheel_drive/meshes/wheel_6.STL" />
      </geometry>
      <material
        name="">
        <color
          rgba="0.501960784313725 0.501960784313725 0.501960784313725 1" />
      </material>
    </visual>
    <collision>
      <origin
        xyz="0 0 0"
        rpy="0 1.5707963267949 1.5707963267949" />
      <geometry>
        <mesh
          filename="package://six_wheel_drive/meshes/wheel_6.STL" />
      </geometry>
    </collision>
  </link>
  <joint
    name="wj6"
    type="continuous">
    <origin
      xyz="-0.22 -0.155 0.027"
      rpy="3.141592654 0 0" />
    <parent
      link="base_link" />
    <child
      link="wheel_6" />
    <axis
      xyz="0 -1 0" />
  </joint>
    <!--
  <link name="velodyne_base_link">
    <inertial>
      <mass value="0.83"/>
      <origin xyz="0 0 0.03585"/>
      <inertia ixx="0.001" ixy="0" ixz="0"
        iyy="0.001" iyz="0"
        izz="0.0011"/>
    </inertial>
    <visual>
      <geometry>
        <mesh filename="package://velodyne_description/meshes/VLP16_base_1.dae" />
      </geometry>
    </visual>
    <visual>
      <geometry>
        <mesh filename="package://velodyne_description/meshes/VLP16_base_2.dae" />
      </geometry>
    </visual>
    <collision>
      <origin rpy="0 0 0" xyz="0 0 0.03585"/>
      <geometry>
        <cylinder radius="0.0516" length="0.0717"/>
      </geometry>
    </collision>
  </link>

  <joint name="velodyne_base_mount_joint" type="fixed">
    <origin xyz="0 0 0.1" rpy="0 0 0" />
    <parent link="base_link"/>
    <child link="velodyne_base_link"/>
  </joint>
    
  <link name="velodyne">
    <inertial>
      <mass value="0.01"/>
      <origin xyz="0 0 0"/>
      <inertia ixx="0" ixy="0" ixz="0" iyy="0" iyz="0" izz="0"/>
    </inertial>
    <visual>
      <origin xyz="0 0 -0.0377" />
      <geometry>
        <mesh filename="package://velodyne_description/meshes/VLP16_scan.dae" />
      </geometry>
    </visual>
  </link>
    
  <joint name="velodyne_base_scan_joint" type="fixed" >
    <origin xyz="0 0 0" rpy="0 0 0" />
    <parent link="velodyne_base_link" />
    <child link="velodyne"/>
  </joint>
-->
  <transmission name="wj1_trans">
    <type>transmission_interface/SimpleTransmission</type>
    <joint name="wj1">
      <hardwareInterface>hardware_interface/VelocityJointInterface</hardwareInterface>
    </joint>
    <actuator name="$wj1_motor">
      <mechanicalReduction>1</mechanicalReduction>
    </actuator>
  </transmission>

  <transmission name="wj2_trans">
    <type>transmission_interface/SimpleTransmission</type>
    <joint name="wj2">
      <hardwareInterface>hardware_interface/VelocityJointInterface</hardwareInterface>
    </joint>
    <actuator name="$wj2_motor">
      <mechanicalReduction>1</mechanicalReduction>
    </actuator>
  </transmission>
  
  <transmission name="wj3_trans">
    <type>transmission_interface/SimpleTransmission</type>
    <joint name="wj3">
      <hardwareInterface>hardware_interface/VelocityJointInterface</hardwareInterface>
    </joint>
    <actuator name="$wj3_motor">
      <mechanicalReduction>1</mechanicalReduction>
    </actuator>
  </transmission>
  
  <transmission name="wj4_trans">
    <type>transmission_interface/SimpleTransmission</type>
    <joint name="wj4">
      <hardwareInterface>hardware_interface/VelocityJointInterface</hardwareInterface>
    </joint>
    <actuator name="$wj4_motor">
      <mechanicalReduction>1</mechanicalReduction>
    </actuator>
  </transmission>

  <transmission name="wj5_trans">
    <type>transmission_interface/SimpleTransmission</type>
    <joint name="wj5">
      <hardwareInterface>hardware_interface/VelocityJointInterface</hardwareInterface>
    </joint>
    <actuator name="$wj5_motor">
      <mechanicalReduction>1</mechanicalReduction>
    </actuator>
  </transmission>
  
  <transmission name="wj6_trans">
    <type>transmission_interface/SimpleTransmission</type>
    <joint name="wj6">
      <hardwareInterface>hardware_interface/VelocityJointInterface</hardwareInterface>
    </joint>
    <actuator name="$wj6_motor">
      <mechanicalReduction>1</mechanicalReduction>
    </actuator>
  </transmission>

  <gazebo reference="wheel_1">
    <mu1 value="200.0"/>
    <mu2 value="100.0"/>
    <kp value="10000000.0" />
    <kd value="1.0" />
    <material>Gazebo/Grey</material>
  </gazebo>

  <gazebo reference="wheel_2">
    <mu1 value="200.0"/>
    <mu2 value="100.0"/>
    <kp value="10000000.0" />
    <kd value="1.0" />
    <material>Gazebo/Grey</material>
  </gazebo>

  <gazebo reference="wheel_3">
    <mu1 value="200.0"/>
    <mu2 value="100.0"/>
    <kp value="10000000.0" />
    <kd value="1.0" />
    <material>Gazebo/Grey</material>
  </gazebo>

  <gazebo reference="wheel_4">
    <mu1 value="200.0"/>
    <mu2 value="100.0"/>
    <kp value="10000000.0" />
    <kd value="1.0" />
    <material>Gazebo/Grey</material>
  </gazebo>

  <gazebo reference="wheel_5">
    <mu1 value="200.0"/>
    <mu2 value="100.0"/>
    <kp value="10000000.0" />
    <kd value="1.0" />
    <material>Gazebo/Grey</material>
  </gazebo>

  <gazebo reference="wheel_6">
    <mu1 value="200.0"/>
    <mu2 value="100.0"/>
    <kp value="10000000.0" />
    <kd value="1.0" />
    <material>Gazebo/Grey</material>
  </gazebo>

<!-- Gazebo requires the velodyne_gazebo_plugins package -->
<!--    <xacro:if value="${gpu}">
      <sensor type="gpu_ray" name="${name}-VLP16">
        <pose>0 0 0 0 0 0</pose>
        <visualize>false</visualize>
        <update_rate>${hz}</update_rate>
        <ray>
          <scan>
            <horizontal>
              <samples>${samples}</samples>
              <resolution>1</resolution>
              <min_angle>${min_angle}</min_angle>
              <max_angle>${max_angle}</max_angle>
            </horizontal>
            <vertical>
              <samples>${lasers}</samples>
              <resolution>1</resolution>
              <min_angle>-${15.0*M_PI/180.0}</min_angle>
              <max_angle> ${15.0*M_PI/180.0}</max_angle>
            </vertical>
          </scan>
          <range>
            <min>${collision_range}</min>
            <max>${max_range+1}</max>
            <resolution>0.001</resolution>
          </range>
          <noise>
            <type>gaussian</type>
            <mean>0.0</mean>
            <stddev>0.0</stddev>
          </noise>
        </ray>
        <plugin name="gazebo_ros_laser_controller" filename="libgazebo_ros_velodyne_gpu_laser.so">
          <topicName>${topic}</topicName>
          <frameName>${name}</frameName>
          <min_range>${min_range}</min_range>
          <max_range>${max_range}</max_range>
          <gaussianNoise>${noise}</gaussianNoise>
        </plugin>
      </sensor> -->
  <gazebo reference="velodyne">
    <sensor type="ray" name="velodyne-VLP16">
      <pose>0 0 0 0 0 0</pose>
      <visualize>false</visualize>
      <update_rate>10</update_rate>
      <ray>
        <scan>
          <horizontal>
            <samples>1875</samples>
            <resolution>1</resolution>
              <min_angle>-3.1415926535897931</min_angle>
              <max_angle>3.1415926535897931</max_angle>
          </horizontal>
          <vertical>
            <samples>16</samples>
            <resolution>1</resolution>
            <min_angle>-0.26</min_angle>
            <max_angle>0.26</max_angle>
          </vertical>
        </scan>
        <range>
          <min>0.9</min>
          <max>131.0</max>
          <resolution>0.001</resolution>
        </range>
        <noise>
          <type>gaussian</type>
          <mean>0.0</mean>
          <stddev>0.0</stddev>
        </noise>
      </ray>
      <plugin name="gazebo_ros_laser_controller" filename="libgazebo_ros_velodyne_laser.so">
        <topicName>/velodyne_points</topicName>
        <frameName>velodyne</frameName>
        <min_range>0.9</min_range>
        <max_range>130.0</max_range>
        <gaussianNoise>0.008</gaussianNoise>
      </plugin>
    </sensor>
  </gazebo>

  <gazebo>
    <plugin name="p3d_base_controller" filename="libgazebo_ros_p3d.so">
      <alwaysOn>true</alwaysOn>
      <updateRate>50.0</updateRate>
      <bodyName>base_link</bodyName>
      <topicName>ground_truth/state</topicName>
      <gaussianNoise>0.01</gaussianNoise>
      <frameName>world</frameName>
      <xyzOffsets>0 0 0</xyzOffsets>
      <rpyOffsets>0 0 0</rpyOffsets>
    </plugin>
  </gazebo>

  <gazebo>
    <plugin name="gazebo_ros_control" filename="libgazebo_ros_control.so">
      <robotNamespace>/</robotNamespace>
    </plugin>
  </gazebo>
  
  
  <gazebo>


		<plugin name="imu_controller" filename="libgazebo_ros_imu.so">
			<alwaysOn>true</alwaysOn>
			<updateRate>20.0</updateRate>
			<bodyName>base_imu_link</bodyName>
			<topicName>imu</topicName>
			<gaussianNoise>0.05</gaussianNoise>
			<frameName>base_imu_link</frameName>
			<xyzOffsets>0 0 0</xyzOffsets>
			<rpyOffset>0 0 0</rpyOffset>
			<serviceName>/default_imu</serviceName>
		</plugin>
	</gazebo>
	
	<link name="base_imu_link">
		<visual>
			<geometry>
				<box size="0.041 0.028 0.002"/>
			</geometry>
			<material name="red">
				<color rgba="1 0 0 1"/>
			</material>
		</visual>
	</link>
	
		<joint name="imu_joint" type="fixed">
		<parent link="base_link"/>
		<child link="base_imu_link"/>
		<origin xyz="0.06 -0.03 0.058" rpy="0 0 0"/>
	</joint>
	
	
	
	
	  <joint name="camera_joint" type="fixed">
    <axis xyz="0 1 0" />
    <origin xyz="0.05 0 0.15" rpy="0 0 0"/>
    <parent link="base_link"/>
    <child link="camera_link"/>
  </joint>

  
  <link name="camera_link">
    <collision>
      <origin xyz="0 0 0" rpy="0 0 0"/>
      <geometry>
    <box size="0.05 0.05 0.05"/>
      </geometry>
    </collision>

    <visual>
      <origin xyz="0 0 0" rpy="0 0 0"/>
      <geometry>
    <box size="0.05 0.05 0.05"/>
      </geometry>
      <material name="red"/>
    </visual>

    <inertial>
      <mass value="1e-5" />
      <origin xyz="0 0 0" rpy="0 0 0"/>
      <inertia ixx="1e-6" ixy="0" ixz="0" iyy="1e-6" iyz="0" izz="1e-6" />
    </inertial>
  </link>
  
   
  <gazebo reference="camera_link">
    <sensor type="camera" name="camera1">
      <update_rate>30.0</update_rate>
      <camera name="head">
        <horizontal_fov>1.3962634</horizontal_fov>
        <image>
          <width>800</width>
          <height>800</height>
          <format>R8G8B8</format>
        </image>
        <clip>
          <near>0.02</near>
          <far>300</far>
        </clip>
        <noise>
          <type>gaussian</type>
          
          <mean>0.0</mean>
          <stddev>0.007</stddev>
        </noise>
      </camera>
      <plugin name="camera_controller" filename="libgazebo_ros_camera.so">
        <alwaysOn>true</alwaysOn>
        <updateRate>0.0</updateRate>
        <cameraName>six_wheel_drive/camera1</cameraName>
        <imageTopicName>image_raw</imageTopicName>
        <cameraInfoTopicName>camera_info</cameraInfoTopicName>
        <frameName>camera_link</frameName>
        <hackBaseline>0.07</hackBaseline>
        <distortionK1>0.0</distortionK1>
        <distortionK2>0.0</distortionK2>
        <distortionK3>0.0</distortionK3>
        <distortionT1>0.0</distortionT1>
        <distortionT2>0.0</distortionT2>
      </plugin>
    </sensor>
  </gazebo>
 
</robot>
